<?xml version="1.0"?>
<!--
F1TENTH Race Car URDF with Complete Physics Properties
Based on: f1tenth_gym and f1tenth_gym_ros
Vehicle: Traxxas Fiesta ST Rally 1/10 Scale
-->
<robot name="f1tenth_racecar">

  <!-- ============================================ -->
  <!-- Materials -->
  <!-- ============================================ -->
  <material name="black">
    <color rgba="0.2 0.2 0.2 1.0"/>
  </material>

  <material name="blue">
    <color rgba="0.3 0.57 1.0 1.0"/>
  </material>

  <material name="red">
    <color rgba="0.8 0.0 0.0 1.0"/>
  </material>

  <!-- ============================================ -->
  <!-- Base Link (Chassis) -->
  <!-- ============================================ -->
  <link name="base_link">
    <inertial>
      <origin xyz="0.165 0 0.09" rpy="0 0 0"/>
      <mass value="3.74"/>  <!-- F1TENTH mass from gym -->
      <inertia
        ixx="0.0456" ixy="0.0" ixz="0.0"
        iyy="0.0683" iyz="0.0"
        izz="0.0971"/>  <!-- Approximated from box model -->
    </inertial>

    <visual>
      <origin xyz="0.165 0 0.09" rpy="0 0 0"/>
      <geometry>
        <box size="0.3302 0.2032 0.1"/>  <!-- wheelbase x width x height -->
      </geometry>
      <material name="blue"/>
    </visual>

    <!-- 바퀴와의 간섭을 없기 위함
    <collision>
      <origin xyz="0.165 0 0.09" rpy="0 0 0"/>
      <geometry>
        <box size="0.3302 0.2032 0.1"/>
      </geometry>
    </collision>
    -->
  </link>

  <!-- ============================================ -->
  <!-- LiDAR (Hokuyo 10LX) -->
  <!-- ============================================ -->
  <joint name="base_to_laser" type="fixed">
    <parent link="base_link"/>
    <child link="laser"/>
    <origin xyz="0.275 0 0.19" rpy="0 0 0"/>  <!-- 0.275m forward, 0.19m high -->
  </joint>

  <link name="laser">
    <inertial>
      <mass value="0.130"/>  <!-- Hokuyo 10LX actual mass -->
      <origin xyz="0 0 0" rpy="0 0 0"/>
      <inertia
        ixx="0.0001" ixy="0.0" ixz="0.0"
        iyy="0.0001" iyz="0.0"
        izz="0.0001"/>
    </inertial>

    <visual>
      <geometry>
        <cylinder radius="0.026" length="0.05"/>
      </geometry>
      <material name="black"/>
    </visual>

    <collision>
      <geometry>
        <cylinder radius="0.026" length="0.05"/>
      </geometry>
    </collision>
  </link>

  <!-- ============================================ -->
  <!-- Rear Wheels (Fixed, Motor Controlled) -->
  <!-- ============================================ -->

  <!-- Left Rear Wheel -->
  <joint name="left_rear_wheel_joint" type="continuous">
    <parent link="base_link"/>
    <child link="left_rear_wheel"/>
    <origin xyz="0 0.12065 0.0508" rpy="0 0 0"/>  <!-- y = (wheel_width + width)/2 -->
    <axis xyz="0 1 0"/>  <!-- Rotation around Y axis -->
  </joint>

  <link name="left_rear_wheel">
    <inertial>
      <mass value="0.34055"/>  <!-- Wheel mass -->
      <origin xyz="0 0 0" rpy="0 0 0"/>
      <inertia
        ixx="0.00026046" ixy="0.0" ixz="0.0"
        iyy="0.00026046" iyz="0.0"
        izz="0.00044"/>  <!-- Cylinder inertia -->
    </inertial>

    <visual>
      <geometry>
        <cylinder radius="0.0508" length="0.0381"/>
      </geometry>
      <material name="black"/>
      <origin xyz="0 0 0" rpy="1.5707963 0 0"/>  <!-- pi/2 rotation -->
    </visual>

    <collision>
      <geometry>
        <cylinder radius="0.0508" length="0.0381"/>
      </geometry>
      <origin xyz="0 0 0" rpy="1.5707963 0 0"/>
    </collision>
  </link>

  <!-- Right Rear Wheel -->
  <joint name="right_rear_wheel_joint" type="continuous">
    <parent link="base_link"/>
    <child link="right_rear_wheel"/>
    <origin xyz="0 -0.12065 0.0508" rpy="0 0 0"/>
    <axis xyz="0 1 0"/>
  </joint>

  <link name="right_rear_wheel">
    <inertial>
      <mass value="0.34055"/>
      <origin xyz="0 0 0" rpy="0 0 0"/>
      <inertia
        ixx="0.00026046" ixy="0.0" ixz="0.0"
        iyy="0.00026046" iyz="0.0"
        izz="0.00044"/>
    </inertial>

    <visual>
      <geometry>
        <cylinder radius="0.0508" length="0.0381"/>
      </geometry>
      <material name="black"/>
      <origin xyz="0 0 0" rpy="1.5707963 0 0"/>
    </visual>

    <collision>
      <geometry>
        <cylinder radius="0.0508" length="0.0381"/>
      </geometry>
      <origin xyz="0 0 0" rpy="1.5707963 0 0"/>
    </collision>
  </link>

  <!-- ============================================ -->
  <!-- Front Wheels (Steerable, Ackermann) -->
  <!-- ============================================ -->

  <!-- Left Front Steering Hinge -->
  <joint name="left_steering_hinge_joint" type="revolute">
    <parent link="base_link"/>
    <child link="left_steering_hinge"/>
    <origin xyz="0.3302 0.12065 0.0508" rpy="0 0 0"/>
    <axis xyz="0 0 1"/>  <!-- Steering axis (vertical) -->
    <limit lower="-0.4189" upper="0.4189" effort="10.0" velocity="3.2"/>  <!-- ±24°, from F1TENTH Gym -->
  </joint>

  <link name="left_steering_hinge">
    <inertial>
      <mass value="0.1"/>
      <origin xyz="0 0 0" rpy="0 0 0"/>
      <inertia
        ixx="0.0001" ixy="0.0" ixz="0.0"
        iyy="0.0001" iyz="0.0"
        izz="0.0001"/>
    </inertial>
  </link>

  <!-- Left Front Wheel -->
  <joint name="left_front_wheel_joint" type="continuous">
    <parent link="left_steering_hinge"/>
    <child link="left_front_wheel"/>
    <origin xyz="0 0 0" rpy="0 0 0"/>
    <axis xyz="0 1 0"/>
  </joint>

  <link name="left_front_wheel">
    <inertial>
      <mass value="0.34055"/>
      <origin xyz="0 0 0" rpy="0 0 0"/>
      <inertia
        ixx="0.00026046" ixy="0.0" ixz="0.0"
        iyy="0.00026046" iyz="0.0"
        izz="0.00044"/>
    </inertial>

    <visual>
      <geometry>
        <cylinder radius="0.0508" length="0.0381"/>
      </geometry>
      <material name="black"/>
      <origin xyz="0 0 0" rpy="1.5707963 0 0"/>
    </visual>

    <collision>
      <geometry>
        <cylinder radius="0.0508" length="0.0381"/>
      </geometry>
      <origin xyz="0 0 0" rpy="1.5707963 0 0"/>
    </collision>
  </link>

  <!-- Right Front Steering Hinge -->
  <joint name="right_steering_hinge_joint" type="revolute">
    <parent link="base_link"/>
    <child link="right_steering_hinge"/>
    <origin xyz="0.3302 -0.12065 0.0508" rpy="0 0 0"/>
    <axis xyz="0 0 1"/>
    <limit lower="-0.4189" upper="0.4189" effort="10.0" velocity="3.2"/>
  </joint>

  <link name="right_steering_hinge">
    <inertial>
      <mass value="0.1"/>
      <origin xyz="0 0 0" rpy="0 0 0"/>
      <inertia
        ixx="0.0001" ixy="0.0" ixz="0.0"
        iyy="0.0001" iyz="0.0"
        izz="0.0001"/>
    </inertial>
  </link>

  <!-- Right Front Wheel -->
  <joint name="right_front_wheel_joint" type="continuous">
    <parent link="right_steering_hinge"/>
    <child link="right_front_wheel"/>
    <origin xyz="0 0 0" rpy="0 0 0"/>
    <axis xyz="0 1 0"/>
  </joint>

  <link name="right_front_wheel">
    <inertial>
      <mass value="0.34055"/>
      <origin xyz="0 0 0" rpy="0 0 0"/>
      <inertia
        ixx="0.00026046" ixy="0.0" ixz="0.0"
        iyy="0.00026046" iyz="0.0"
        izz="0.00044"/>
    </inertial>

    <visual>
      <geometry>
        <cylinder radius="0.0508" length="0.0381"/>
      </geometry>
      <material name="black"/>
      <origin xyz="0 0 0" rpy="1.5707963 0 0"/>
    </visual>

    <collision>
      <geometry>
        <cylinder radius="0.0508" length="0.0381"/>
      </geometry>
      <origin xyz="0 0 0" rpy="1.5707963 0 0"/>
    </collision>
  </link>

</robot>
